Traceback (most recent call last):
  File "/Users/tychen/workspaces/thinkdsm/.venv/lib/python3.13/site-packages/jupyter_core/utils/__init__.py", line 154, in wrapped
    asyncio.get_running_loop()
    ~~~~~~~~~~~~~~~~~~~~~~~~^^
RuntimeError: no running event loop

During handling of the above exception, another exception occurred:

Traceback (most recent call last):
  File "/Users/tychen/workspaces/thinkdsm/.venv/lib/python3.13/site-packages/jupyter_cache/executors/utils.py", line 58, in single_nb_execution
    executenb(
    ~~~~~~~~~^
        nb,
        ^^^
    ...<4 lines>...
        **kwargs,
        ^^^^^^^^^
    )
    ^
  File "/Users/tychen/workspaces/thinkdsm/.venv/lib/python3.13/site-packages/nbclient/client.py", line 1319, in execute
    return NotebookClient(nb=nb, resources=resources, km=km, **kwargs).execute()
           ~~~~~~~~~~~~~~~~~~~~~~~~~~~~~~~~~~~~~~~~~~~~~~~~~~~~~~~~~~~~~~~~~~~^^
  File "/Users/tychen/workspaces/thinkdsm/.venv/lib/python3.13/site-packages/jupyter_core/utils/__init__.py", line 158, in wrapped
    return loop.run_until_complete(inner)
           ~~~~~~~~~~~~~~~~~~~~~~~^^^^^^^
  File "/usr/local/Cellar/python@3.13/3.13.3_1/Frameworks/Python.framework/Versions/3.13/lib/python3.13/asyncio/base_events.py", line 719, in run_until_complete
    return future.result()
           ~~~~~~~~~~~~~^^
  File "/Users/tychen/workspaces/thinkdsm/.venv/lib/python3.13/site-packages/nbclient/client.py", line 709, in async_execute
    await self.async_execute_cell(
        cell, index, execution_count=self.code_cells_executed + 1
    )
  File "/Users/tychen/workspaces/thinkdsm/.venv/lib/python3.13/site-packages/nbclient/client.py", line 1062, in async_execute_cell
    await self._check_raise_for_error(cell, cell_index, exec_reply)
  File "/Users/tychen/workspaces/thinkdsm/.venv/lib/python3.13/site-packages/nbclient/client.py", line 918, in _check_raise_for_error
    raise CellExecutionError.from_cell_and_msg(cell, exec_reply_content)
nbclient.exceptions.CellExecutionError: An error occurred while executing the following cell:
------------------
from diagram import make_frame, Stack

d1 = dict(line1=line1, line2=line2)
frame1 = make_frame(d1, name='__main__', dy=-0.3, loc='left')

d2 = dict(part1=line1, part2=line2, cat=line1+line2)
frame2 = make_frame(d2, name='cat_twice', dy=-0.3, 
                    offsetx=0.03, loc='left')

d3 = dict(string=line1+line2)
frame3 = make_frame(d3, name='print_twice', 
                    offsetx=0.04, offsety=-0.3, loc='left')

d4 = {"?": line1+line2}
frame4 = make_frame(d4, name='print', 
                    offsetx=-0.22, offsety=0, loc='left')

stack = Stack([frame1, frame2, frame3, frame4], dy=-0.8)
------------------


[31mModuleNotFoundError[39m[31m:[39m No module named 'matplotlib'


