Traceback (most recent call last):
  File "/Users/tychen/workspace/thinkdsm/.venv/lib/python3.13/site-packages/jupyter_core/utils/__init__.py", line 154, in wrapped
    asyncio.get_running_loop()
    ~~~~~~~~~~~~~~~~~~~~~~~~^^
RuntimeError: no running event loop

During handling of the above exception, another exception occurred:

Traceback (most recent call last):
  File "/Users/tychen/workspace/thinkdsm/.venv/lib/python3.13/site-packages/jupyter_cache/executors/utils.py", line 58, in single_nb_execution
    executenb(
    ~~~~~~~~~^
        nb,
        ^^^
    ...<4 lines>...
        **kwargs,
        ^^^^^^^^^
    )
    ^
  File "/Users/tychen/workspace/thinkdsm/.venv/lib/python3.13/site-packages/nbclient/client.py", line 1319, in execute
    return NotebookClient(nb=nb, resources=resources, km=km, **kwargs).execute()
           ~~~~~~~~~~~~~~~~~~~~~~~~~~~~~~~~~~~~~~~~~~~~~~~~~~~~~~~~~~~~~~~~~~~^^
  File "/Users/tychen/workspace/thinkdsm/.venv/lib/python3.13/site-packages/jupyter_core/utils/__init__.py", line 158, in wrapped
    return loop.run_until_complete(inner)
           ~~~~~~~~~~~~~~~~~~~~~~~^^^^^^^
  File "/usr/local/Cellar/python@3.13/3.13.7/Frameworks/Python.framework/Versions/3.13/lib/python3.13/asyncio/base_events.py", line 725, in run_until_complete
    return future.result()
           ~~~~~~~~~~~~~^^
  File "/Users/tychen/workspace/thinkdsm/.venv/lib/python3.13/site-packages/nbclient/client.py", line 709, in async_execute
    await self.async_execute_cell(
        cell, index, execution_count=self.code_cells_executed + 1
    )
  File "/Users/tychen/workspace/thinkdsm/.venv/lib/python3.13/site-packages/nbclient/client.py", line 1062, in async_execute_cell
    await self._check_raise_for_error(cell, cell_index, exec_reply)
  File "/Users/tychen/workspace/thinkdsm/.venv/lib/python3.13/site-packages/nbclient/client.py", line 918, in _check_raise_for_error
    raise CellExecutionError.from_cell_and_msg(cell, exec_reply_content)
nbclient.exceptions.CellExecutionError: An error occurred while executing the following cell:
------------------
from diagram import make_frame, Stack

d1 = dict(line1=line1, line2=line2)
frame1 = make_frame(d1, name='__main__', dy=-0.3, loc='left')

d2 = dict(part1=line1, part2=line2, cat=line1+line2)
frame2 = make_frame(d2, name='cat_twice', dy=-0.3, 
                    offsetx=0.03, loc='left')

d3 = dict(string=line1+line2)
frame3 = make_frame(d3, name='print_twice', 
                    offsetx=0.04, offsety=-0.3, loc='left')

d4 = {"?": line1+line2}
frame4 = make_frame(d4, name='print', 
                    offsetx=-0.22, offsety=0, loc='left')

stack = Stack([frame1, frame2, frame3, frame4], dy=-0.8)
------------------


[31m---------------------------------------------------------------------------[39m
[31mModuleNotFoundError[39m                       Traceback (most recent call last)
[36mCell[39m[36m [39m[32mIn[4][39m[32m, line 1[39m
[32m----> [39m[32m1[39m [38;5;28;01mfrom[39;00m[38;5;250m [39m[34;01mdiagram[39;00m[38;5;250m [39m[38;5;28;01mimport[39;00m make_frame, Stack
[32m      3[39m d1 = [38;5;28mdict[39m(line1=line1, line2=line2)
[32m      4[39m frame1 = make_frame(d1, name=[33m'[39m[33m__main__[39m[33m'[39m, dy=-[32m0.3[39m, loc=[33m'[39m[33mleft[39m[33m'[39m)

[36mFile [39m[32m~/workspace/thinkdsm/chapters/04-control-structure/diagram.py:1[39m
[32m----> [39m[32m1[39m [38;5;28;01mimport[39;00m[38;5;250m [39m[34;01mmatplotlib[39;00m[34;01m.[39;00m[34;01mpyplot[39;00m[38;5;250m [39m[38;5;28;01mas[39;00m[38;5;250m [39m[34;01mplt[39;00m
[32m      2[39m [38;5;28;01mimport[39;00m[38;5;250m [39m[34;01mmatplotlib[39;00m[34;01m.[39;00m[34;01mpatches[39;00m[38;5;250m [39m[38;5;28;01mas[39;00m[38;5;250m [39m[34;01mpatches[39;00m
[32m      4[39m [38;5;28;01mfrom[39;00m[38;5;250m [39m[34;01mmatplotlib[39;00m[34;01m.[39;00m[34;01mtransforms[39;00m[38;5;250m [39m[38;5;28;01mimport[39;00m Bbox, TransformedBbox

[31mModuleNotFoundError[39m: No module named 'matplotlib'

